<mujoco model="panda_leap_tac3d">
  <compiler angle="radian" />
  <asset>
    <mesh name="link0" file="./panda/meshes/visual/link0.stl" />
    <mesh name="link1" file="./panda/meshes/visual/link1.stl" />
    <mesh name="link2" file="./panda/meshes/visual/link2.stl" />
    <mesh name="link3" file="./panda/meshes/visual/link3.stl" />
    <mesh name="link4" file="./panda/meshes/visual/link4.stl" />
    <mesh name="link5" file="./panda/meshes/visual/link5.stl" />
    <mesh name="link6" file="./panda/meshes/visual/link6.stl" />
    <mesh name="link7" file="./panda/meshes/visual/link7.stl" />
    <mesh name="palm_lower" file="./leap_hand/meshes/palm_lower.stl" />
    <mesh name="mcp_joint" file="./leap_hand/meshes/mcp_joint.stl" />
    <mesh name="pip" file="./leap_hand/meshes/pip.stl" />
    <mesh name="dip" file="./leap_hand/meshes/dip.stl" />
    <mesh name="fingertip_base_tac3d" file="./leap_hand/meshes/fingertip_base_tac3d.stl" />
    <mesh name="thumb_pip" file="./leap_hand/meshes/thumb_pip.stl" />
    <mesh name="thumb_dip" file="./leap_hand/meshes/thumb_dip.stl" />
    <mesh name="thumb_fingertip_base_tac3d" file="./leap_hand/meshes/thumb_fingertip_base_tac3d.stl" />
    <mesh name="fingertip_tac3d" file="./leap_hand/meshes/fingertip_tac3d.stl" />
    </asset>
  <worldbody>
    <body name="base" gravcomp="1">
      <body name="panda_link0" gravcomp="1">
        <geom type="mesh" contype="0" conaffinity="0" group="1" density="0" rgba="1 1 1 1" mesh="link0" />
        <geom type="mesh" rgba="1 1 1 1" mesh="link0" />
        <body name="panda_link1" pos="0 0 0.333" gravcomp="1">
          <joint name="panda_joint1" pos="0 0 0" axis="0 0 1" range="-2.9671 2.9671" actuatorfrcrange="-87 87" class="panda" />
          <geom type="mesh" contype="0" conaffinity="0" group="1" density="0" rgba="1 1 1 1" mesh="link1" />
          <geom type="mesh" rgba="1 1 1 1" mesh="link1" />
          <body name="panda_link2" quat="0.707107 -0.707107 0 0" gravcomp="1">
            <joint name="panda_joint2" pos="0 0 0" axis="0 0 1" range="-1.8326 1.8326" actuatorfrcrange="-87 87" class="panda" />
            <geom type="mesh" contype="0" conaffinity="0" group="1" density="0" rgba="1 1 1 1" mesh="link2" />
            <geom type="mesh" rgba="1 1 1 1" mesh="link2" />
            <body name="panda_link3" pos="0 -0.316 0" quat="0.707107 0.707107 0 0" gravcomp="1">
              <joint name="panda_joint3" pos="0 0 0" axis="0 0 1" range="-2.9671 2.9671" actuatorfrcrange="-87 87" class="panda" />
              <geom type="mesh" contype="0" conaffinity="0" group="1" density="0" rgba="1 1 1 1" mesh="link3" />
              <geom type="mesh" rgba="1 1 1 1" mesh="link3" />
              <body name="panda_link4" pos="0.0825 0 0" quat="0.707107 0.707107 0 0" gravcomp="1">
                <joint name="panda_joint4" pos="0 0 0" axis="0 0 1" range="-3.1416 0" actuatorfrcrange="-87 87" class="panda" />
                <geom type="mesh" contype="0" conaffinity="0" group="1" density="0" rgba="1 1 1 1" mesh="link4" />
                <geom type="mesh" rgba="1 1 1 1" mesh="link4" />
                <body name="panda_link5" pos="-0.0825 0.384 0" quat="0.707107 -0.707107 0 0" gravcomp="1">
                  <joint name="panda_joint5" pos="0 0 0" axis="0 0 1" range="-2.9671 2.9671" actuatorfrcrange="-12 12" class="panda" />
                  <geom type="mesh" contype="0" conaffinity="0" group="1" density="0" rgba="1 1 1 1" mesh="link5" />
                  <geom type="mesh" rgba="1 1 1 1" mesh="link5" />
                  <body name="panda_link6" quat="0.707107 0.707107 0 0" gravcomp="1">
                    <joint name="panda_joint6" pos="0 0 0" axis="0 0 1" range="-0.0873 3.8223" actuatorfrcrange="-12 12" class="panda" />
                    <geom type="mesh" contype="0" conaffinity="0" group="1" density="0" rgba="1 1 1 1" mesh="link6" />
                    <geom type="mesh" rgba="1 1 1 1" mesh="link6" />
                    <body name="panda_link7" pos="0.088 0 0" quat="0.707107 0.707107 0 0" gravcomp="1">
                      <joint name="panda_joint7" pos="0 0 0" axis="0 0 1" range="-2.9671 2.9671" actuatorfrcrange="-12 12" class="panda" />
                      <geom type="mesh" contype="0" conaffinity="0" group="1" density="0" rgba="1 1 1 1" mesh="link7" />
                      <geom type="mesh" rgba="1 1 1 1" mesh="link7" />
                      <body name="panda_link8" pos="0 0 0.107" gravcomp="1">
                        <body name="palm_lower" pos="0.03 -0.07 0.02" quat="0 0.923879 -0.382684 0" gravcomp="1">
                          <inertial pos="0 0 0" quat="0.497095 0.495942 -0.509424 0.497419" mass="0.237" diaginertia="0.000529322 0.000354076 0.000260868" />
                          <geom pos="-0.0200952 0.0257578 -0.0347224" quat="1 0 0 0" type="mesh" contype="0" conaffinity="0" group="1" density="0" rgba="0.603922 0.14902 0.14902 1" mesh="palm_lower" />
                          <geom pos="-0.0200952 0.0257578 -0.0347224" quat="1 0 0 0" type="mesh" rgba="0.603922 0.14902 0.14902 1" mesh="palm_lower" />
                          <body name="mcp_joint" pos="-0.00709525 0.0230578 -0.0187224" quat="0.5 0.5 0.5 -0.5" gravcomp="1">
                            <inertial pos="0 0 0" quat="0.388585 0.626468 -0.324549 0.592628" mass="0.044" diaginertia="1.47756e-05 1.31982e-05 6.0802e-06" />
                            <joint name="joint_1" pos="0 0 0" axis="0 0 -1" range="-0.314 2.23" actuatorfrcrange="-0.95 0.95" />
                            <geom pos="0.0084069 0.00776624 0.0146574" quat="1 0 0 0" type="mesh" contype="0" conaffinity="0" group="1" density="0" rgba="0.866667 0.866667 0.0509804 1" mesh="mcp_joint" />
                            <geom pos="0.0084069 0.00776624 0.0146574" quat="1 0 0 0" type="mesh" rgba="0.866667 0.866667 0.0509804 1" mesh="mcp_joint" />
                            <body name="pip" pos="-0.0122 0.0381 0.0145" quat="0.5 -0.5 -0.5 0.5" gravcomp="1">
                              <inertial pos="0 0 0" quat="0.709913 0.704273 -0.000363156 0.00475427" mass="0.032" diaginertia="4.7981e-06 4.23406e-06 2.86184e-06" />
                              <joint name="joint_0" pos="0 0 0" axis="0 0 -1" range="-1.047 1.047" actuatorfrcrange="-0.95 0.95" damping="0.003" />
                              <geom pos="0.00964336 0.0003 0.000784034" quat="0.5 -0.5 -0.5 -0.5" type="mesh" contype="0" conaffinity="0" group="1" density="0" rgba="0.74902 0.74902 0.74902 1" mesh="pip" />
                              <geom pos="0.00964336 0.0003 0.000784034" quat="0.5 -0.5 -0.5 -0.5" type="mesh" rgba="0.74902 0.74902 0.74902 1" mesh="pip" />
                              <body name="dip" pos="0.015 0.0143 -0.013" quat="0.5 0.5 -0.5 0.5" gravcomp="1">
                                <inertial pos="0 0 0" quat="-0.252689 0.659216 0.238844 0.666735" mass="0.037" diaginertia="6.68256e-06 6.24841e-06 5.02002e-06" />
                                <joint name="joint_2" pos="0 0 0" axis="0 0 -1" range="-0.506 1.885" actuatorfrcrange="-0.95 0.95" />
                                <geom pos="0.0211334 -0.00843212 0.00978509" quat="0 -1 0 0" type="mesh" contype="0" conaffinity="0" group="1" density="0" rgba="0.866667 0.866667 0.0509804 1" mesh="dip" />
                                <geom pos="0.0211334 -0.00843212 0.00978509" quat="0 -1 0 0" type="mesh" rgba="0.866667 0.866667 0.0509804 1" mesh="dip" />
                                <body name="fingertip" pos="-4.08806e-09 -0.0361 0.0002" gravcomp="1">
                                  <inertial pos="0 0 0" quat="0.706755 0.706755 0.0223155 0.0223155" mass="0.016" diaginertia="3.37527e-06 2.863e-06 1.54873e-06" />
                                  <joint name="joint_3" pos="0 0 0" axis="0 0 -1" range="-0.366 2.042" actuatorfrcrange="-0.95 0.95" />
                                  <geom pos="0.0149864 -0.0169142 0.0144" quat="0.707107 0 0.707107 0" type="mesh" contype="0" conaffinity="0" group="1" density="0" rgba="0.866667 0.866667 0.0509804 1" mesh="fingertip_base_tac3d" />
                                  <geom pos="0.0149864 -0.0169142 0.0144" quat="0.707107 0 0.707107 0" type="mesh" rgba="0.866667 0.866667 0.0509804 1" mesh="fingertip_base_tac3d" />
                                  <body name="fingertip_new" pos="0 -0.017 0.0145" quat="0 -0.707107 0 0.707107" gravcomp="1">
                                    <inertial pos="0.0001 0.0382 0.0075" mass="1e-10" diaginertia="1e-10 1e-10 1e-10" />
                                    <geom pos="0.0001 0.0382 0.0075" quat="0.707107 0 0 0.707107" type="mesh" contype="0" conaffinity="0" group="1" density="0" rgba="0.866667 0.866667 0.0509804 1" mesh="fingertip_tac3d" />
                                    <geom pos="0.0001 0.0382 0.0075" quat="0.707107 0 0 0.707107" type="mesh" rgba="0.866667 0.866667 0.0509804 1" mesh="fingertip_tac3d" name="fingertip_new_g" />
                                    <body name="finger1_tip_center" pos="0 0.038 0.01" quat="0.707107 0 0 0.707107" gravcomp="1">
                                      <body name="finger1_tip_center_lower" pos="-0.02 0 0" gravcomp="1" />
                                      </body>
                                    </body>
                                  </body>
                                </body>
                              </body>
                            </body>
                          <body name="mcp_joint_2" pos="-0.00709525 -0.0223922 -0.0187224" quat="0.5 0.5 0.5 -0.5" gravcomp="1">
                            <inertial pos="0 0 0" quat="0.388585 0.626468 -0.324549 0.592628" mass="0.044" diaginertia="1.47756e-05 1.31982e-05 6.0802e-06" />
                            <joint name="joint_5" pos="0 0 0" axis="0 0 -1" range="-0.314 2.23" actuatorfrcrange="-0.95 0.95" />
                            <geom pos="0.0084069 0.00776624 0.0146574" quat="1 0 0 0" type="mesh" contype="0" conaffinity="0" group="1" density="0" rgba="0.866667 0.866667 0.0509804 1" mesh="mcp_joint" />
                            <geom pos="0.0084069 0.00776624 0.0146574" quat="1 0 0 0" type="mesh" rgba="0.866667 0.866667 0.0509804 1" mesh="mcp_joint" />
                            <body name="pip_2" pos="-0.0122 0.0381 0.0145" quat="0.5 -0.5 -0.5 0.5" gravcomp="1">
                              <inertial pos="0 0 0" quat="0.709913 0.704273 -0.000363156 0.00475427" mass="0.032" diaginertia="4.7981e-06 4.23406e-06 2.86184e-06" />
                              <joint name="joint_4" pos="0 0 0" axis="0 0 -1" range="-1.047 1.047" actuatorfrcrange="-0.95 0.95" />
                              <geom pos="0.00964336 0.0003 0.000784034" quat="0.5 -0.5 -0.5 -0.5" type="mesh" contype="0" conaffinity="0" group="1" density="0" rgba="0.74902 0.74902 0.74902 1" mesh="pip" />
                              <geom pos="0.00964336 0.0003 0.000784034" quat="0.5 -0.5 -0.5 -0.5" type="mesh" rgba="0.74902 0.74902 0.74902 1" mesh="pip" />
                              <body name="dip_2" pos="0.015 0.0143 -0.013" quat="0.5 0.5 -0.5 0.5" gravcomp="1">
                                <inertial pos="0 0 0" quat="-0.252689 0.659216 0.238844 0.666735" mass="0.037" diaginertia="6.68256e-06 6.24841e-06 5.02002e-06" />
                                <joint name="joint_6" pos="0 0 0" axis="0 0 -1" range="-0.506 1.885" actuatorfrcrange="-0.95 0.95" />
                                <geom pos="0.0211334 -0.00843212 0.00978509" quat="0 -1 0 0" type="mesh" contype="0" conaffinity="0" group="1" density="0" rgba="0.866667 0.866667 0.0509804 1" mesh="dip" />
                                <geom pos="0.0211334 -0.00843212 0.00978509" quat="0 -1 0 0" type="mesh" rgba="0.866667 0.866667 0.0509804 1" mesh="dip" />
                                <body name="fingertip_2" pos="0 -0.0361 0.0002" gravcomp="1">
                                  <inertial pos="0 0 0" quat="0.706755 0.706755 0.0223155 0.0223155" mass="0.016" diaginertia="3.37527e-06 2.863e-06 1.54873e-06" />
                                  <joint name="joint_7" pos="0 0 0" axis="0 0 -1" range="-0.366 2.042" actuatorfrcrange="-0.95 0.95" />
                                  <geom pos="0.0149864 -0.0169142 0.0144" quat="0.707107 0 0.707107 0" type="mesh" contype="0" conaffinity="0" group="1" density="0" rgba="0.866667 0.866667 0.0509804 1" mesh="fingertip_base_tac3d" />
                                  <geom pos="0.0149864 -0.0169142 0.0144" quat="0.707107 0 0.707107 0" type="mesh" rgba="0.866667 0.866667 0.0509804 1" mesh="fingertip_base_tac3d" />
                                  <body name="fingertip_2_new" pos="0 -0.017 0.0145" quat="0 -0.707107 0 0.707107" gravcomp="1">
                                    <inertial pos="0.0001 0.0382 0.0075" mass="1e-10" diaginertia="1e-10 1e-10 1e-10" />
                                    <geom pos="0.0001 0.0382 0.0075" quat="0.707107 0 0 0.707107" type="mesh" contype="0" conaffinity="0" group="1" density="0" rgba="0.866667 0.866667 0.0509804 1" mesh="fingertip_tac3d" />
                                    <geom pos="0.0001 0.0382 0.0075" quat="0.707107 0 0 0.707107" type="mesh" rgba="0.866667 0.866667 0.0509804 1" mesh="fingertip_tac3d" name="fingertip_2_new_g" />
                                    <body name="finger2_tip_center" pos="0 0.038 0.01" quat="0.707107 0 0 0.707107" gravcomp="1">
                                      <body name="finger2_tip_center_lower" pos="-0.02 0 0" gravcomp="1" />
                                      </body>
                                    </body>
                                  </body>
                                </body>
                              </body>
                            </body>
                          <body name="mcp_joint_3" pos="-0.00709525 -0.0678422 -0.0187224" quat="0.5 0.5 0.5 -0.5" gravcomp="1">
                            <inertial pos="0 0 0" quat="0.388585 0.626468 -0.324549 0.592628" mass="0.044" diaginertia="1.47756e-05 1.31982e-05 6.0802e-06" />
                            <joint name="joint_9" pos="0 0 0" axis="0 0 -1" range="-0.314 2.23" actuatorfrcrange="-0.95 0.95" />
                            <geom pos="0.0084069 0.00776624 0.0146574" quat="1 0 0 0" type="mesh" contype="0" conaffinity="0" group="1" density="0" rgba="0.866667 0.866667 0.0509804 1" mesh="mcp_joint" />
                            <geom pos="0.0084069 0.00776624 0.0146574" quat="1 0 0 0" type="mesh" rgba="0.866667 0.866667 0.0509804 1" mesh="mcp_joint" />
                            <body name="pip_3" pos="-0.0122 0.0381 0.0145" quat="0.5 -0.5 -0.5 0.5" gravcomp="1">
                              <inertial pos="0 0 0" quat="0.709913 0.704273 -0.000363156 0.00475427" mass="0.032" diaginertia="4.7981e-06 4.23406e-06 2.86184e-06" />
                              <joint name="joint_8" pos="0 0 0" axis="0 0 -1" range="-1.047 1.047" actuatorfrcrange="-0.95 0.95" />
                              <geom pos="0.00964336 0.0003 0.000784034" quat="0.5 -0.5 -0.5 -0.5" type="mesh" contype="0" conaffinity="0" group="1" density="0" rgba="0.74902 0.74902 0.74902 1" mesh="pip" />
                              <geom pos="0.00964336 0.0003 0.000784034" quat="0.5 -0.5 -0.5 -0.5" type="mesh" rgba="0.74902 0.74902 0.74902 1" mesh="pip" />
                              <body name="dip_3" pos="0.015 0.0143 -0.013" quat="0.5 0.5 -0.5 0.5" gravcomp="1">
                                <inertial pos="0 0 0" quat="-0.252689 0.659216 0.238844 0.666735" mass="0.037" diaginertia="6.68256e-06 6.24841e-06 5.02002e-06" />
                                <joint name="joint_10" pos="0 0 0" axis="0 0 -1" range="-0.506 1.885" actuatorfrcrange="-0.95 0.95" />
                                <geom pos="0.0211334 -0.00843212 0.00978509" quat="0 -1 0 0" type="mesh" contype="0" conaffinity="0" group="1" density="0" rgba="0.866667 0.866667 0.0509804 1" mesh="dip" />
                                <geom pos="0.0211334 -0.00843212 0.00978509" quat="0 -1 0 0" type="mesh" rgba="0.866667 0.866667 0.0509804 1" mesh="dip" />
                                <body name="fingertip_3" pos="0 -0.0361 0.0002" gravcomp="1">
                                  <inertial pos="0 0 0" quat="0.706755 0.706755 0.0223155 0.0223155" mass="0.016" diaginertia="3.37527e-06 2.863e-06 1.54873e-06" />
                                  <joint name="joint_11" pos="0 0 0" axis="0 0 -1" range="-0.366 2.042" actuatorfrcrange="-0.95 0.95" />
                                  <geom pos="0.0149864 -0.0169142 0.0144" quat="0.707107 0 0.707107 0" type="mesh" contype="0" conaffinity="0" group="1" density="0" rgba="0.866667 0.866667 0.0509804 1" mesh="fingertip_base_tac3d" />
                                  <geom pos="0.0149864 -0.0169142 0.0144" quat="0.707107 0 0.707107 0" type="mesh" rgba="0.866667 0.866667 0.0509804 1" mesh="fingertip_base_tac3d" />
                                  <body name="fingertip_3_new" pos="0 -0.017 0.0145" quat="0 -0.707107 0 0.707107" gravcomp="1">
                                    <inertial pos="0.0001 0.0382 0.0075" mass="1e-10" diaginertia="1e-10 1e-10 1e-10" />
                                    <geom pos="0.0001 0.0382 0.0075" quat="0.707107 0 0 0.707107" type="mesh" contype="0" conaffinity="0" group="1" density="0" rgba="0.866667 0.866667 0.0509804 1" mesh="fingertip_tac3d" />
                                    <geom pos="0.0001 0.0382 0.0075" quat="0.707107 0 0 0.707107" type="mesh" rgba="0.866667 0.866667 0.0509804 1" mesh="fingertip_tac3d" name="fingertip_3_new_g" />
                                    <body name="finger3_tip_center" pos="0 0.038 0.01" quat="0.707107 0 0 0.707107" gravcomp="1">
                                      <body name="finger3_tip_center_lower" pos="-0.02 0 0" gravcomp="1" />
                                      </body>
                                    </body>
                                  </body>
                                </body>
                              </body>
                            </body>
                          <body name="pip_4" pos="-0.0693952 -0.00124224 -0.0216224" quat="0.707107 0 0.707107 0" gravcomp="1">
                            <inertial pos="0 0 0" quat="0.709913 0.704273 -0.000363156 0.00475427" mass="0.032" diaginertia="4.7981e-06 4.23406e-06 2.86184e-06" />
                            <joint name="joint_12" pos="0 0 0" axis="0 0 -1" range="-0.349 2.094" actuatorfrcrange="-0.95 0.95" />
                            <geom pos="-0.00535664 0.0003 0.000784034" quat="0.5 -0.5 -0.5 -0.5" type="mesh" contype="0" conaffinity="0" group="1" density="0" rgba="0.74902 0.74902 0.74902 1" mesh="pip" />
                            <geom pos="-0.00535664 0.0003 0.000784034" quat="0.5 -0.5 -0.5 -0.5" type="mesh" rgba="0.74902 0.74902 0.74902 1" mesh="pip" />
                            <body name="thumb_pip" pos="0 0.0143 -0.013" quat="0.5 0.5 -0.5 0.5" gravcomp="1">
                              <inertial pos="0 0 0" mass="0.003" diaginertia="5.93e-07 5.49e-07 2.24e-07" />
                              <joint name="joint_13" pos="0 0 0" axis="0 0 -1" range="-0.47 2.443" actuatorfrcrange="-0.95 0.95" />
                              <geom pos="0.0119619 0 -0.0158526" quat="0.707107 0.707107 0 0" type="mesh" contype="0" conaffinity="0" group="1" density="0" rgba="0.866667 0.866667 0.0509804 1" mesh="thumb_pip" />
                              <geom pos="0.0119619 0 -0.0158526" quat="0.707107 0.707107 0 0" type="mesh" rgba="0.866667 0.866667 0.0509804 1" mesh="thumb_pip" />
                              <body name="thumb_dip" pos="0 0.0145 -0.017" quat="0.707107 -0.707107 0 0" gravcomp="1">
                                <inertial pos="0 0 0" quat="0.708624 0.704906 0.00637342 0.0303153" mass="0.038" diaginertia="8.48742e-06 7.67823e-06 3.82835e-06" />
                                <joint name="joint_14" pos="0 0 0" axis="0 0 -1" range="-1.2 1.9" actuatorfrcrange="-0.95 0.95" />
                                <geom pos="0.0439687 0.057953 -0.00862868" quat="1 0 0 0" type="mesh" contype="0" conaffinity="0" group="1" density="0" rgba="0.866667 0.866667 0.0509804 1" mesh="thumb_dip" />
                                <geom pos="0.0439687 0.057953 -0.00862868" quat="1 0 0 0" type="mesh" rgba="0.866667 0.866667 0.0509804 1" mesh="thumb_dip" />
                                <body name="thumb_fingertip" pos="0 0.0466 0.0002" quat="0 0 0 1" gravcomp="1">
                                  <inertial pos="0 0 0" quat="0.704307 0.709299 0.006848 -0.0282727" mass="0.049" diaginertia="2.03882e-05 1.98443e-05 4.32049e-06" />
                                  <joint name="joint_15" pos="0 0 0" axis="0 0 -1" range="-1.34 1.88" actuatorfrcrange="-0.95 0.95" />
                                  <geom pos="0.0120595 -0.0357597 -0.0290929" quat="1 0 0 0" type="mesh" contype="0" conaffinity="0" group="1" density="0" rgba="0.603922 0.14902 0.14902 1" mesh="thumb_fingertip_base_tac3d" />
                                  <geom pos="0.0120595 -0.0357597 -0.0290929" quat="1 0 0 0" type="mesh" rgba="0.603922 0.14902 0.14902 1" mesh="thumb_fingertip_base_tac3d" />
                                  <body name="thumb_fingertip_new" pos="0 -0.03 -0.0145" quat="0 -0.707107 0 0.707107" gravcomp="1">
                                    <inertial pos="0 0 0" mass="1e-10" diaginertia="1e-10 1e-10 1e-10" />
                                    <geom pos="0 0.0358 0.0085" quat="0.707107 0 0 0.707107" type="mesh" contype="0" conaffinity="0" group="1" density="0" rgba="0.866667 0.866667 0.0509804 1" mesh="fingertip_tac3d" />
                                    <geom pos="0 0.0358 0.0085" quat="0.707107 0 0 0.707107" type="mesh" rgba="0.866667 0.866667 0.0509804 1" mesh="fingertip_tac3d" name="thumb_fingertip_new_g" />
                                    <body name="thumb_tip_center" pos="0 0.0355 0.011" quat="0.707107 0 0 0.707107" gravcomp="1">
                                      <body name="thumb_tip_center_lower" pos="-0.02 0 0" gravcomp="1" />
                                      </body>
                                    </body>
                                  </body>
                                </body>
                              </body>
                            </body>
                          <body name="wrist" pos="-0.16 -0.04 -0.01" quat="0.707107 0 0.707107 0" gravcomp="1" />
                          </body>
                        </body>
                      </body>
                    </body>
                  </body>
                </body>
              </body>
            </body>
          </body>
        </body>
      </body>
    </worldbody>
  </mujoco>
